<?xml version='1.0'?>
<sdf version='1.7'>
  <model name='TR_Anchor'>
    <link name='tr_link'>
      <inertial>
        <mass>1</mass>
        <inertia>
          <ixx>0.145833</ixx>
          <ixy>0</ixy>
          <ixz>0</ixz>
          <iyy>0.145833</iyy>
          <iyz>0</iyz>
          <izz>0.125</izz>
        </inertia>
        <pose>0 0 0 0 -0 0</pose>
      </inertial>
      <pose>1.98363 -1e-05 1.44572 0 -0 0</pose>
      <gravity>0</gravity>
      <self_collide>0</self_collide>
      <static>1</static>
      <enable_wind>0</enable_wind>
      <visual name='visual'>
        <pose>0 0 0 1.57 -0 0</pose>
        <geometry>
          <cylinder>
            <radius>0.1</radius>
            <length>0.4</length>
          </cylinder>
        </geometry>
        <material>
          <lighting>1</lighting>
          <script>
            <uri>file://media/materials/scripts/gazebo.material</uri>
            <name>Gazebo/Grey</name>
          </script>
          <shader type='pixel'>
            <normal_map>__default__</normal_map>
          </shader>
          <ambient>0.3 0.3 0.3 1</ambient>
          <diffuse>0.7 0.7 0.7 1</diffuse>
          <specular>0.01 0.01 0.01 1</specular>
          <emissive>0 0 0 1</emissive>
        </material>
        <transparency>0</transparency>
        <cast_shadows>1</cast_shadows>
      </visual>
      <collision name='collision'>
        <geometry>
          <cylinder>
            <radius>0.1</radius>
            <length>0.4</length>
          </cylinder>
        </geometry>
        <surface>
          <contact>
            <collide_without_contact>true</collide_without_contact>
          </contact>
        </surface>
      </collision>
    </link>
    <link name='tr_dummy'>
      <pose>1.98363 -1e-05 1.44572 0 -0 0</pose>
    </link>
    <link name='tr_prismatic'>
      <pose>1.98363 -1e-05 1.44572 0 -0 0</pose>
    </link>
    <joint name='Universal Joint Top Right' type='universal'>
      <parent>tr_link</parent>
      <child>tr_dummy</child>
      <pose>0 0 0 0 -0 0</pose>
      <axis>
        <xyz>0 1 0</xyz>
        <limit>
          <lower>-1</lower>
          <upper>1</upper>
          <effort>-1</effort>
          <velocity>-1</velocity>
        </limit>
        <dynamics>
          <spring_reference>0</spring_reference>
          <spring_stiffness>0</spring_stiffness>
          <damping>0</damping>
          <friction>0</friction>
        </dynamics>
      </axis>
      <axis2>
        <xyz>0 0 1</xyz>
        <limit>
          <lower>-1</lower>
          <upper>1</upper>
          <effort>-1</effort>
          <velocity>-1</velocity>
        </limit>
        <dynamics>
          <spring_reference>0</spring_reference>
          <spring_stiffness>0</spring_stiffness>
          <damping>0</damping>
          <friction>0</friction>
        </dynamics>
      </axis2>
      <physics>
        <ode>
          <limit>
            <cfm>0</cfm>
            <erp>0.2</erp>
          </limit>
          <suspension>
            <cfm>0</cfm>
            <erp>0.2</erp>
          </suspension>
        </ode>
      </physics>
    </joint>
    <joint name='Prismatic Joint Top Right' type='prismatic'>
      <child>tr_prismatic</child>
      <parent>tr_dummy</parent>
      <pose>0 0 0 0 -0 0</pose>
      <axis>
        <xyz>0 0 -1</xyz>
        <limit>
          <lower>-2</lower>
          <upper>2</upper>
          <effort>-1</effort>
          <velocity>-1</velocity>
        </limit>
        <dynamics>
          <spring_reference>0</spring_reference>
          <spring_stiffness>0</spring_stiffness>
          <damping>0</damping>
          <friction>0</friction>
        </dynamics>
      </axis>
      <physics>
        <ode>
          <limit>
            <cfm>0</cfm>
            <erp>0.2</erp>
          </limit>
          <suspension>
            <cfm>0</cfm>
            <erp>0.2</erp>
          </suspension>
        </ode>
      </physics>
    </joint>
    <static>0</static>
    <plugin filename="libignition-gazebo-detachable-joint-system.so" name="ignition::gazebo::systems::DetachableJoint">
       <parent_link>tr_prismatic</parent_link>
       <child_model>wallbot</child_model>
       <child_link>link_1_0</child_link>
       <topic>/wallbot_tr_join/detach</topic>
    </plugin>
  </model>
</sdf>

