<?xml version="1.0" ?>
<robot name="Wallbot_V2_Robot">
  <link name="link_0">
    <inertial>
      <mass value="1"/>
      <inertia ixx="0.166667" ixy="0" ixz="0" iyy="0.166667" iyz="0" izz="0.166667"/>
      <origin rpy="0 -0 0" xyz="0 0 0"/>
    </inertial>
    <origin rpy="0 -0 0" xyz="0.015 0 0.005"/>
    <kinematic>0</kinematic>
    <enable_wind>0</enable_wind>
    <visual>
      <origin rpy="0 -0 0" xyz="0 0 0"/>
      <geometry>
        <box size="0.8 0.5 0.6"/>
      </geometry>
      <material name="Gazebo/Grey">
        <color rgba="0.7 0.7 0.7 1"/>
        <shader type="pixel">
          <normal_map>__default__</normal_map>
        </shader>
        <ambient>1 0.1 0.1 1</ambient>
        <diffuse>0.7 0.7 0.7 1</diffuse>
        <specular>0.01 0.01 0.01 1</specular>
        <emissive>0 0 0 1</emissive>
      </material>
      <transparency>0</transparency>
      <cast_shadows>1</cast_shadows>
    </visual>
  </link>
  <link name="link_0_0">
    <inertial>
      <mass value="1"/>
      <inertia ixx="0.145833" ixy="0" ixz="0" iyy="0.145833" iyz="0" izz="0.125"/>
      <origin rpy="0 -0 0" xyz="0 0 -2"/>
    </inertial>
    <origin rpy="3.14159 -0.901593 3.14159" xyz="0.415 0 0.205"/>
    <kinematic>0</kinematic>
    <enable_wind>0</enable_wind>
    <visual>
      <origin rpy="0 -0 0" xyz="0 0 -2"/>
      <geometry>
        <cylinder length="4" radius="0.01"/>
      </geometry>
      <material name="Gazebo/Grey">
        <color rgba="0.7 0.7 0.7 1"/>
        <shader type="pixel">
          <normal_map>__default__</normal_map>
        </shader>
        <ambient>0.3 0.3 0.3 1</ambient>
        <diffuse>0.7 0.7 0.7 1</diffuse>
        <specular>0.01 0.01 0.01 1</specular>
        <emissive>0 0 0 1</emissive>
      </material>
      <transparency>0</transparency>
      <cast_shadows>1</cast_shadows>
    </visual>
  </link>
  <link name="link_0_0_clone">
    <inertial>
      <mass value="1"/>
      <inertia ixx="0.145833" ixy="0" ixz="0" iyy="0.145833" iyz="0" izz="0.125"/>
      <origin rpy="0 -0 0" xyz="0 0 -2"/>
    </inertial>
    <origin rpy="-3.14159 0.9 -3.14159" xyz="-0.385 0 0.205"/>
    <kinematic>0</kinematic>
    <enable_wind>0</enable_wind>
    <visual>
      <origin rpy="0 -0 0" xyz="0 0 -2"/>
      <geometry>
        <cylinder length="4" radius="0.01"/>
      </geometry>
      <material name="Gazebo/Grey">
        <color rgba="0.7 0.7 0.7 1"/>
        <shader type="pixel">
          <normal_map>__default__</normal_map>
        </shader>
        <ambient>0.3 0.3 0.3 1</ambient>
        <diffuse>0.7 0.7 0.7 1</diffuse>
        <specular>0.01 0.01 0.01 1</specular>
        <emissive>0 0 0 1</emissive>
      </material>
      <transparency>0</transparency>
      <cast_shadows>1</cast_shadows>
    </visual>
  </link>
  <link name="link_0_0_clone_0">
    <inertial>
      <mass value="1"/>
      <inertia ixx="0.145833" ixy="0" ixz="0" iyy="0.145833" iyz="0" izz="0.125"/>
      <origin rpy="0 -0 0" xyz="0 0 -2"/>
    </inertial>
    <origin rpy="1.1e-05 -0.9 -5e-06" xyz="0.415 0 -0.195"/>
    <kinematic>0</kinematic>
    <enable_wind>0</enable_wind>
    <visual>
      <origin rpy="0 -0 0" xyz="0 0 -2"/>
      <geometry>
        <cylinder length="4" radius="0.01"/>
      </geometry>
      <material name="Gazebo/Grey">
        <color rgba="0.7 0.7 0.7 1"/>
        <shader type="pixel">
          <normal_map>__default__</normal_map>
        </shader>
        <ambient>0.3 0.3 0.3 1</ambient>
        <diffuse>0.7 0.7 0.7 1</diffuse>
        <specular>0.01 0.01 0.01 1</specular>
        <emissive>0 0 0 1</emissive>
      </material>
      <transparency>0</transparency>
      <cast_shadows>1</cast_shadows>
    </visual>
  </link>
  <link name="link_0_0_clone_1">
    <inertial>
      <mass value="1"/>
      <inertia ixx="0.145833" ixy="0" ixz="0" iyy="0.145833" iyz="0" izz="0.125"/>
      <origin rpy="0 -0 0" xyz="0 0 -2"/>
    </inertial>
    <origin rpy="1.1e-05 0.9 -5e-06" xyz="-0.385 0 -0.195"/>
    <kinematic>0</kinematic>
    <enable_wind>0</enable_wind>
    <visual>
      <origin rpy="0 -0 0" xyz="0 0 -2"/>
      <geometry>
        <cylinder length="4" radius="0.01"/>
      </geometry>
      <material name="Gazebo/Grey">
        <color rgba="0.7 0.7 0.7 1"/>
        <shader type="pixel">
          <normal_map>__default__</normal_map>
        </shader>
        <ambient>0.3 0.3 0.3 1</ambient>
        <diffuse>0.7 0.7 0.7 1</diffuse>
        <specular>0.01 0.01 0.01 1</specular>
        <emissive>0 0 0 1</emissive>
      </material>
      <transparency>0</transparency>
      <cast_shadows>1</cast_shadows>
    </visual>
  </link>
  <link name="link_1">
    <inertial>
      <mass value="1"/>
      <inertia ixx="0.1" ixy="0" ixz="0" iyy="0.1" iyz="0" izz="0.1"/>
      <origin rpy="0 -0 0" xyz="0 0 0"/>
    </inertial>
    <origin rpy="0 -0 0" xyz="-0.385 0 0.205"/>
    <kinematic>0</kinematic>
    <enable_wind>0</enable_wind>
    <visual>
      <origin rpy="0 -0 0" xyz="0 0 0"/>
      <geometry>
        <sphere radius="0.075"/>
      </geometry>
      <material name="Gazebo/Grey">
        <color rgba="0.7 0.7 0.7 1"/>
        <shader type="pixel">
          <normal_map>__default__</normal_map>
        </shader>
        <ambient>0.3 0.3 0.3 1</ambient>
        <diffuse>0.7 0.7 0.7 1</diffuse>
        <specular>0.01 0.01 0.01 1</specular>
        <emissive>0 0 0 1</emissive>
      </material>
      <transparency>0</transparency>
      <cast_shadows>1</cast_shadows>
    </visual>
  </link>
  <link name="link_1_0">
    <inertial>
      <mass value="1"/>
      <inertia ixx="0.1" ixy="0" ixz="0" iyy="0.1" iyz="0" izz="0.1"/>
      <origin rpy="0 -0 0" xyz="0 0 0"/>
    </inertial>
    <origin rpy="0 -0 0" xyz="-1.95165 1e-06 1.44822"/>
    <kinematic>0</kinematic>
    <enable_wind>0</enable_wind>
    <visual>
      <origin rpy="0 -0 0" xyz="0 0 0"/>
      <geometry>
        <sphere radius="0.01"/>
      </geometry>
      <material name="Gazebo/Grey">
        <color rgba="0.7 0.7 0.7 1"/>
        <shader type="pixel">
          <normal_map>__default__</normal_map>
        </shader>
        <ambient>0.3 0.3 0.3 1</ambient>
        <diffuse>0.7 0.7 0.7 1</diffuse>
        <specular>0.01 0.01 0.01 1</specular>
        <emissive>0 0 0 1</emissive>
      </material>
      <transparency>0</transparency>
      <cast_shadows>1</cast_shadows>
    </visual>
  </link>
  <link name="link_1_0_clone">
    <inertial>
      <mass value="1"/>
      <inertia ixx="0.1" ixy="0" ixz="0" iyy="0.1" iyz="0" izz="0.1"/>
      <origin rpy="0 -0 0" xyz="0 0 0"/>
    </inertial>
    <origin rpy="0 -0 0" xyz="1.98363 -1e-05 1.44572"/>
    <kinematic>0</kinematic>
    <enable_wind>0</enable_wind>
    <visual>
      <origin rpy="0 -0 0" xyz="0 0 0"/>
      <geometry>
        <sphere radius="0.01"/>
      </geometry>
      <material name="Gazebo/Grey">
        <color rgba="0.7 0.7 0.7 1"/>
        <shader type="pixel">
          <normal_map>__default__</normal_map>
        </shader>
        <ambient>0.3 0.3 0.3 1</ambient>
        <diffuse>0.7 0.7 0.7 1</diffuse>
        <specular>0.01 0.01 0.01 1</specular>
        <emissive>0 0 0 1</emissive>
      </material>
      <transparency>0</transparency>
      <cast_shadows>1</cast_shadows>
    </visual>
  </link>
  <link name="link_1_0_clone_0">
    <inertial>
      <mass value="1"/>
      <inertia ixx="0.1" ixy="0" ixz="0" iyy="0.1" iyz="0" izz="0.1"/>
      <origin rpy="0 -0 0" xyz="0 0 0"/>
    </inertial>
    <origin rpy="1.1e-05 -0.9 -5e-06" xyz="1.98165 1.4e-05 -1.43822"/>
    <kinematic>0</kinematic>
    <enable_wind>0</enable_wind>
    <visual>
      <origin rpy="0 -0 0" xyz="0 0 0"/>
      <geometry>
        <sphere radius="0.01"/>
      </geometry>
      <material name="Gazebo/Grey">
        <color rgba="0.7 0.7 0.7 1"/>
        <shader type="pixel">
          <normal_map>__default__</normal_map>
        </shader>
        <ambient>0.3 0.3 0.3 1</ambient>
        <diffuse>0.7 0.7 0.7 1</diffuse>
        <specular>0.01 0.01 0.01 1</specular>
        <emissive>0 0 0 1</emissive>
      </material>
      <transparency>0</transparency>
      <cast_shadows>1</cast_shadows>
    </visual>
  </link>
  <link name="link_1_0_clone_1">
    <inertial>
      <mass value="1"/>
      <inertia ixx="0.1" ixy="0" ixz="0" iyy="0.1" iyz="0" izz="0.1"/>
      <origin rpy="0 -0 0" xyz="0 0 0"/>
    </inertial>
    <origin rpy="1.1e-05 0.9 -5e-06" xyz="-1.95165 3e-05 -1.43822"/>
    <kinematic>0</kinematic>
    <enable_wind>0</enable_wind>
    <visual>
      <origin rpy="0 -0 0" xyz="0 0 0"/>
      <geometry>
        <sphere radius="0.01"/>
      </geometry>
      <material name="Gazebo/Grey">
        <color rgba="0.7 0.7 0.7 1"/>
        <shader type="pixel">
          <normal_map>__default__</normal_map>
        </shader>
        <ambient>0.3 0.3 0.3 1</ambient>
        <diffuse>0.7 0.7 0.7 1</diffuse>
        <specular>0.01 0.01 0.01 1</specular>
        <emissive>0 0 0 1</emissive>
      </material>
      <transparency>0</transparency>
      <cast_shadows>1</cast_shadows>
    </visual>
  </link>
  <link name="link_1_clone">
    <inertial>
      <mass value="1"/>
      <inertia ixx="0.1" ixy="0" ixz="0" iyy="0.1" iyz="0" izz="0.1"/>
      <origin rpy="0 -0 0" xyz="0 0 0"/>
    </inertial>
    <origin rpy="0 -0 0" xyz="0.415 0 0.205"/>
    <kinematic>0</kinematic>
    <enable_wind>0</enable_wind>
    <visual>
      <origin rpy="0 -0 0" xyz="0 0 0"/>
      <geometry>
        <sphere radius="0.075"/>
      </geometry>
      <material name="Gazebo/Grey">
        <color rgba="0.7 0.7 0.7 1"/>
        <shader type="pixel">
          <normal_map>__default__</normal_map>
        </shader>
        <ambient>0.3 0.3 0.3 1</ambient>
        <diffuse>0.7 0.7 0.7 1</diffuse>
        <specular>0.01 0.01 0.01 1</specular>
        <emissive>0 0 0 1</emissive>
      </material>
      <transparency>0</transparency>
      <cast_shadows>1</cast_shadows>
    </visual>
  </link>
  <link name="link_1_clone_0">
    <inertial>
      <mass value="1"/>
      <inertia ixx="0.1" ixy="0" ixz="0" iyy="0.1" iyz="0" izz="0.1"/>
      <origin rpy="0 -0 0" xyz="0 0 0"/>
    </inertial>
    <origin rpy="0 -0 0" xyz="0.415 0 -0.195"/>
    <kinematic>0</kinematic>
    <enable_wind>0</enable_wind>
    <visual>
      <origin rpy="0 -0 0" xyz="0 0 0"/>
      <geometry>
        <sphere radius="0.075"/>
      </geometry>
      <material name="Gazebo/Grey">
        <color rgba="0.7 0.7 0.7 1"/>
        <shader type="pixel">
          <normal_map>__default__</normal_map>
        </shader>
        <ambient>0.3 0.3 0.3 1</ambient>
        <diffuse>0.7 0.7 0.7 1</diffuse>
        <specular>0.01 0.01 0.01 1</specular>
        <emissive>0 0 0 1</emissive>
      </material>
      <transparency>0</transparency>
      <cast_shadows>1</cast_shadows>
    </visual>
  </link>
  <link name="link_1_clone_1">
    <inertial>
      <mass value="1"/>
      <inertia ixx="0.1" ixy="0" ixz="0" iyy="0.1" iyz="0" izz="0.1"/>
      <origin rpy="0 -0 0" xyz="0 0 0"/>
    </inertial>
    <origin rpy="0 -0 0" xyz="-0.385 0 -0.195"/>
    <kinematic>0</kinematic>
    <enable_wind>0</enable_wind>
    <visual>
      <origin rpy="0 -0 0" xyz="0 0 0"/>
      <geometry>
        <sphere radius="0.075"/>
      </geometry>
      <material name="Gazebo/Grey">
        <color rgba="0.7 0.7 0.7 1"/>
        <shader type="pixel">
          <normal_map>__default__</normal_map>
        </shader>
        <ambient>0.3 0.3 0.3 1</ambient>
        <diffuse>0.7 0.7 0.7 1</diffuse>
        <specular>0.01 0.01 0.01 1</specular>
        <emissive>0 0 0 1</emissive>
      </material>
      <transparency>0</transparency>
      <cast_shadows>1</cast_shadows>
    </visual>
  </link>
  <link name="link_3">
    <inertial>
      <mass value="1"/>
      <inertia ixx="0.145833" ixy="0" ixz="0" iyy="0.145833" iyz="0" izz="0.125"/>
      <origin rpy="0 -0 0" xyz="0 0 0"/>
    </inertial>
    <origin rpy="0 -0 0" xyz="-1.95165 1e-06 1.44822"/>
    <kinematic>1</kinematic>
    <enable_wind>0</enable_wind>
    <visual>
      <origin rpy="1.57 -0 0" xyz="0 0 0"/>
      <geometry>
        <cylinder length="0.4" radius="0.1"/>
      </geometry>
      <material name="Gazebo/Grey">
        <color rgba="0.7 0.7 0.7 1"/>
        <shader type="pixel">
          <normal_map>__default__</normal_map>
        </shader>
        <ambient>0.3 0.3 0.3 1</ambient>
        <diffuse>0.7 0.7 0.7 1</diffuse>
        <specular>0.01 0.01 0.01 1</specular>
        <emissive>0 0 0 1</emissive>
      </material>
      <transparency>0</transparency>
      <cast_shadows>1</cast_shadows>
    </visual>
  </link>
  <link name="link_3_clone">
    <inertial>
      <mass value="1"/>
      <inertia ixx="0.145833" ixy="0" ixz="0" iyy="0.145833" iyz="0" izz="0.125"/>
      <origin rpy="0 -0 0" xyz="0 0 0"/>
    </inertial>
    <origin rpy="0 -0 0" xyz="1.98363 -1e-05 1.44572"/>
    <kinematic>1</kinematic>
    <enable_wind>0</enable_wind>
    <visual>
      <origin rpy="1.57 -0 0" xyz="0 0 0"/>
      <geometry>
        <cylinder length="0.4" radius="0.1"/>
      </geometry>
      <material name="Gazebo/Grey">
        <color rgba="0.7 0.7 0.7 1"/>
        <shader type="pixel">
          <normal_map>__default__</normal_map>
        </shader>
        <ambient>0.3 0.3 0.3 1</ambient>
        <diffuse>0.7 0.7 0.7 1</diffuse>
        <specular>0.01 0.01 0.01 1</specular>
        <emissive>0 0 0 1</emissive>
      </material>
      <transparency>0</transparency>
      <cast_shadows>1</cast_shadows>
    </visual>
  </link>
  <link name="link_3_clone_0">
    <inertial>
      <mass value="1"/>
      <inertia ixx="0.145833" ixy="0" ixz="0" iyy="0.145833" iyz="0" izz="0.125"/>
      <origin rpy="0 -0 0" xyz="0 0 0"/>
    </inertial>
    <origin rpy="1.1e-05 -0.9 -5e-06" xyz="1.98165 1.4e-05 -1.43822"/>
    <kinematic>1</kinematic>
    <enable_wind>0</enable_wind>
    <visual>
      <origin rpy="1.57 -0 0" xyz="0 0 0"/>
      <geometry>
        <cylinder length="0.4" radius="0.1"/>
      </geometry>
      <material name="Gazebo/Grey">
        <color rgba="0.7 0.7 0.7 1"/>
        <shader type="pixel">
          <normal_map>__default__</normal_map>
        </shader>
        <ambient>0.3 0.3 0.3 1</ambient>
        <diffuse>0.7 0.7 0.7 1</diffuse>
        <specular>0.01 0.01 0.01 1</specular>
        <emissive>0 0 0 1</emissive>
      </material>
      <transparency>0</transparency>
      <cast_shadows>1</cast_shadows>
    </visual>
  </link>
  <link name="link_3_clone_1">
    <inertial>
      <mass value="1"/>
      <inertia ixx="0.145833" ixy="0" ixz="0" iyy="0.145833" iyz="0" izz="0.125"/>
      <origin rpy="0 -0 0" xyz="0 0 0"/>
    </inertial>
    <origin rpy="1.1e-05 0.9 -5e-06" xyz="-1.95165 3e-05 -1.43822"/>
    <kinematic>1</kinematic>
    <enable_wind>0</enable_wind>
    <visual>
      <origin rpy="1.57 -0 0" xyz="0 0 0"/>
      <geometry>
        <cylinder length="0.4" radius="0.1"/>
      </geometry>
      <material name="Gazebo/Grey">
        <color rgba="0.7 0.7 0.7 1"/>
        <shader type="pixel">
          <normal_map>__default__</normal_map>
        </shader>
        <ambient>0.3 0.3 0.3 1</ambient>
        <diffuse>0.7 0.7 0.7 1</diffuse>
        <specular>0.01 0.01 0.01 1</specular>
        <emissive>0 0 0 1</emissive>
      </material>
      <transparency>0</transparency>
      <cast_shadows>1</cast_shadows>
    </visual>
  </link>
  <joint name="Prismatic Joint Bottom Left" type="prismatic">
    <parent link="link_1_0_clone_0"/>
    <child link="link_0_0_clone_0"/>
    <origin rpy="0 -0 0" xyz="0 0 0"/>
    <axis xyz="0 0 1"/>
    <limit effort="-1" lower="-2" upper="2" velocity="-1"/>
    <dynamics damping="0" friction="0" spring_reference="0" spring_stiffness="0"/>
  </joint>
  <joint name="Prismatic Joint Bottom Right" type="prismatic">
    <parent link="link_1_0_clone_1"/>
    <child link="link_0_0_clone_1"/>
    <origin rpy="0 -0 0" xyz="0 0 0"/>
    <axis xyz="0 0 1"/>
    <limit effort="-1" lower="-2" upper="2" velocity="-1"/>
    <dynamics damping="0" friction="0" spring_reference="0" spring_stiffness="0"/>
  </joint>
  <joint name="Prismatic Joint Top Left" type="prismatic">
    <parent link="link_1_0_clone"/>
    <child link="link_0_0"/>
    <origin rpy="0 -0 0" xyz="0 0 0"/>
    <axis xyz="0 0 1"/>
    <limit effort="-1" lower="-2" upper="2" velocity="-1"/>
    <dynamics damping="0" friction="0" spring_reference="0" spring_stiffness="0"/>
  </joint>
  <joint name="Prismatic Joint Top Right" type="prismatic">
    <parent link="link_1_0"/>
    <child link="link_0_0_clone"/>
    <origin rpy="0 -0 0" xyz="0 0 0"/>
    <axis xyz="0 0 -1"/>
    <limit effort="-1" lower="-2" upper="2" velocity="-1"/>
    <dynamics damping="0" friction="0" spring_reference="0" spring_stiffness="0"/>
  </joint>
  <joint name="Universal Join Bottom Left" type="revolute">
    <parent link="link_3_clone_0"/>
    <child link="link_1_0_clone_0"/>
    <origin rpy="0 -0 0" xyz="0 0 0"/>
    <axis xyz="0 0 1"/>
    <axis2>
      <xyz>0 1 0</xyz>
      <limit effort="-1" lower="-1" upper="1" velocity="-1"/>
      <dynamics damping="0" friction="0" spring_reference="0" spring_stiffness="0"/>
    </axis2>
    <limit effort="-1" lower="-1" upper="1" velocity="-1"/>
    <dynamics damping="0" friction="0" spring_reference="0" spring_stiffness="0"/>
  </joint>
  <joint name="Universal Joint Bottom Right" type="revolute">
    <parent link="link_3_clone_1"/>
    <child link="link_1_0_clone_1"/>
    <origin rpy="0 -0 0" xyz="0 0 0"/>
    <axis xyz="0 1 0"/>
    <axis2>
      <xyz>0 0 1</xyz>
      <limit effort="-1" lower="-1" upper="1" velocity="-1"/>
      <dynamics damping="0" friction="0" spring_reference="0" spring_stiffness="0"/>
    </axis2>
    <limit effort="-1" lower="-1" upper="1" velocity="-1"/>
    <dynamics damping="0" friction="0" spring_reference="0" spring_stiffness="0"/>
  </joint>
  <joint name="Universal Joint Top Left" type="revolute">
    <parent link="link_3_clone"/>
    <child link="link_1_0_clone"/>
    <origin rpy="0 -0 0" xyz="0 0 0"/>
    <axis xyz="1 0 0"/>
    <axis2>
      <xyz>0 0 1</xyz>
      <limit effort="-1" lower="-1e+16" upper="1e+16" velocity="-1"/>
      <dynamics damping="0" friction="0" spring_reference="0" spring_stiffness="0"/>
    </axis2>
    <limit effort="-1" lower="-1" upper="1" velocity="-1"/>
    <dynamics damping="0" friction="0" spring_reference="0" spring_stiffness="0"/>
  </joint>
  <joint name="Universal Joint Top Right" type="revolute">
    <parent link="link_3"/>
    <child link="link_1_0"/>
    <origin rpy="0 -0 0" xyz="0 0 0"/>
    <axis xyz="0 1 0"/>
    <axis2>
      <xyz>0 0 1</xyz>
      <limit effort="-1" lower="-1" upper="1" velocity="-1"/>
      <dynamics damping="0" friction="0" spring_reference="0" spring_stiffness="0"/>
    </axis2>
    <limit effort="-1" lower="-1" upper="1" velocity="-1"/>
    <dynamics damping="0" friction="0" spring_reference="0" spring_stiffness="0"/>
  </joint>
  <joint name="link_0_JOINT_0" type="fixed">
    <parent link="link_0"/>
    <child link="link_1"/>
    <origin rpy="0 -0 0" xyz="0 0 0"/>
  </joint>
  <joint name="link_0_JOINT_1" type="fixed">
    <parent link="link_0"/>
    <child link="link_1_clone_1"/>
    <origin rpy="0 -0 0" xyz="0 0 0"/>
  </joint>
  <joint name="link_0_JOINT_2" type="fixed">
    <parent link="link_0"/>
    <child link="link_1_clone"/>
    <origin rpy="0 -0 0" xyz="0 0 0"/>
  </joint>
  <joint name="link_0_JOINT_3" type="fixed">
    <parent link="link_0"/>
    <child link="link_1_clone_0"/>
    <origin rpy="0 -0 0" xyz="0 0 0"/>
  </joint>
  <joint name="link_1_JOINT_2" type="revolute">
    <parent link="link_1"/>
    <child link="link_0_0_clone"/>
    <origin rpy="0 -0 0" xyz="0 0 0"/>
    <axis xyz="1 0 0"/>
    <limit lower="-1.57" upper="1.57" effort="5" velocity="1"/>
  </joint>
  <joint name="link_1_clone_0_JOINT_4" type="revolute">
    <parent link="link_1_clone_0"/>
    <child link="link_0_0_clone_0"/>
    <origin rpy="0 -0 0" xyz="0 0 0"/>
    <axis xyz="1 0 0"/>
    <limit lower="-1.57" upper="1.57" effort="5" velocity="1"/>
  </joint>
  <joint name="link_1_clone_1_JOINT_5" type="revolute">
    <parent link="link_1_clone_1"/>
    <child link="link_0_0_clone_1"/>
    <origin rpy="0 -0 0" xyz="0 0 0"/>
    <axis xyz="1 0 0"/>
    <limit lower="-1.57" upper="1.57" effort="5" velocity="1"/>
  </joint>
  <joint name="link_1_clone_JOINT_1" type="revolute">
    <parent link="link_1_clone"/>
    <child link="link_0_0"/>
    <origin rpy="0 -0 0" xyz="0 0 0"/>
    <axis xyz="1 0 0"/>
    <limit lower="-1.57" upper="1.57" effort="5" velocity="1"/>
  </joint>
  <allow_auto_disable>1</allow_auto_disable>
  <material name="Gazebo/Grey">
    <color rgba=".3 .3 .3 1.0"/>
  </material>
</robot>
